Workbook

Sheet Category Summary
A1: Spend by Category
A2: Totals of legible line items only. Several receipts were partially scanned, so these are floors, not full receipt totals (see the detailed per-receipt workbook for printed grand totals).
A4: Category | B4: # Items | C4: Legible Total
A5: Meats, Poultry & Seafood | B5: 39 | C5: ='By Category'!D45 -> 5387.25
A6: Cheeses | B6: 15 | C6: ='By Category'!D64 -> 598.85
A7: Fruits & Vegetables | B7: 106 | C7: ='By Category'!D174 -> 2004.19
A8: Dairy & Eggs | B8: 6 | C8: ='By Category'!D184 -> 161.95
A9: Frozen | B9: 9 | C9: ='By Category'!D197 -> 148.8
A10: Bakery, Snacks & Candy | B10: 20 | C10: ='By Category'!D221 -> 392.33
A11: Pantry, Sauces & Seasonings | B11: 47 | C11: ='By Category'!D272 -> 1644.98
A12: Beverages | B12: 17 | C12: ='By Category'!D293 -> 280.99
A13: Supplies & Disposables | B13: 60 | C13: ='By Category'!D357 -> 1217.31
A14: Discounts & Adjustments | B14: 14 | C14: ='By Category'!D375 -> -1261.3
A15: TOTAL (legible items) | B15: =SUM(B5:B14) -> 333 | C15: =SUM(C5:C14) -> 10575.35

Sheet By Category
A1: Restaurant Depot — Items by Category
A2: Every legible line item across all receipts (Store #802, buyer Erin Hunnewell), grouped by category. Each row is one line as rung on a receipt; the Source column points to the receipt sheet in the detailed workbook. Voids/discounts are shown as negatives.
A4: Meats, Poultry & Seafood (39 items)
A5: Item | B5: Detail | C5: Qty | D5: Amount | E5: Source (receipt)
A6: BCN LEIDY 1822 15# HW | C6: 1 | D6: 54.85 | E6: Moose I13372 0722
A7: BCN LEIDY 1822 15# HW | C7: 1 | D7: 54.85 | E7: Moose I13372 0722
A8: BCN LEIDY 1822 15# HW | C8: 1 | D8: 54.85 | E8: Moose I13372 0722
A9: BCN LEIDY 1822 15# HW | C9: 1 | D9: 54.85 | E9: Moose I13372 0722
A10: BF ANG GROUND CHUK R/W | B10: 60.4 LB @ $5.36/LB | C10: 1 | D10: 323.74 | E10: Mad Moose 0806
A11: BF ANG GROUND CHUK R/W | B11: 60.9 LB @ $4.93/LB | C11: 1 | D11: 300.24 | E11: Mad Moose 0806
A12: BF ANG GROUND CHUK R/W | B12: 63.3 LB @ $4.93/LB | C12: 1 | D12: 312.07 | E12: Mad Moose 0806
A13: BF ANG GROUND CHUK R/W | B13: 63.6 LB @ $4.93/LB | C13: 1 | D13: 313.55 | E13: Mad Moose 0806
A14: BF ANG GROUND CHUK R/W | B14: 59.2 LB @ $5.09/LB | C14: 1 | D14: 301.33 | E14: Mad Moose I9681 0722
A15: BF ANG GROUND CHUK R/W | B15: 60.6 LB @ $4.89/LB | C15: 1 | D15: 296.33 | E15: Mad Moose I9681 0722
A16: BF ANG GROUND CHUK R/W | B16: 60.2 LB @ $4.89/LB | C16: 1 | D16: 294.38 | E16: Mad Moose I9681 0722
A17: BF ANG GROUND CHUK R/W | B17: 60.6 LB @ $4.89/LB | C17: 1 | D17: 296.33 | E17: Mad Moose I9681 0722
A18: BF ANG GROUND CHUK R/W | B18: 59.0 LB @ $4.89/LB | C18: 1 | D18: 288.51 | E18: Mad Moose I9681 0722
A19: BF ANG GROUND CHUK R/W | B19: 60.0 LB @ $4.89/LB | C19: 1 | D19: 293.4 | E19: Mad Moose I9681 0722
A20: BF ANG GROUND CHUK R/W | B20: 59.1 LB @ $4.89/LB | C20: 1 | D20: 289 | E20: Mad Moose I9681 0722
A21: CHIC BNLS THIGH HALAL | B21: 40 LB @ $1.74/LB | C21: 1 | D21: 69.6 | E21: Mad Moose 0806
... A34: CHIC WNG JUMB PRTY | B34: 40 LB @ $1.95/LB | C34: 1 | D34: 78 | E34: Mad Moose I9681 0722
A35: CHX GV GRILL HALAL 10LBS | C35: 1 | D35: 63.77 | E35: Mad Moose I968 0722
A36: EZ POKE TUNA 10LB | C36: 1 | D36: 59.9 | E36: Mad Moose I968 0722
A37: FRSHBRNZIN 16-800 R/W | B37: 22.05 LB @ $7.59/LB | C37: 1 | D37: 167.36 | E37: Mad Moose I968 0722
A38: GROUND PORK 5LBS | B38: C · 1cs/7u | C38: 7 | D38: 69.62 | E38: Mad Moose 0806
A39: LI SOUND OYSTERS 50CT | C39: 1 | D39: 42.31 | E39: Mad Moose 0806
A40: LI SOUND OYSTERS 50CT | C40: 1 | D40: 42.31 | E40: Mad Moose 0806
A41: PEPPERNI 12.5# MAM | B41: C · 1cs/2u | C41: 2 | D41: 80.54 | E41: Mad Moose I9681 0722
A42: PROSCIUTTO DANIELE | B42: 13.21 LB @ $6.49/LB | C42: 1 | D42: 85.73 | E42: Mad Moose 0806
A43: TURKEY RTC FOIL | B43: 23.38 LB @ $3.96/LB | C43: 1 | D43: 92.58 | E43: Mad Moose 0815 recall
A44: TURKEY RTC FOIL | B44: 24.66 LB @ $3.96/LB | C44: 1 | D44: 97.65 | E44: Mad Moose I9681 0722
A45: Meats, Poultry & Seafood — subtotal | D45: =SUM(D6:D44) -> 5387.25
A47: Cheeses (15 items)
A48: Item | B48: Detail | C48: Qty | D48: Amount | E48: Source (receipt)
A49: CHZ ASIAGO SHRD SI 4/5LB | B49: U | C49: 1 | D49: 21.42 | E49: Receipt S01
A50: CHZ BLU CRUM TC 5# | B50: U | C50: 1 | D50: 18.4 | E50: Moose Loose 0818
A51: CHZ CREAM LOAF JF 3LB | B51: C · 1cs/10u | C51: 10 | D51: 64.07 | E51: Moose Loose 0818
A52: CHZ GOAT PAIL 2/4LB2 | B52: C · 1cs/2u | C52: 2 | D52: 55.24 | E52: Mad Moose 0815 recall
A53: CHZ GOAT PAIL 2/4LB2 | B53: C · 1cs/2u | C53: 2 | D53: 55.24 | E53: Mad Moose 0815 recall
A54: CHZ GOAT PAIL 2/4LB2 | B54: C · 1cs/2u | C54: 2 | D54: 55.24 | E54: Moose Loose 0818
...
