Workbook

Sheet Summary
A1: Restaurant Depot — Receipts Summary
A3: Store #802 · Colonie, NY · buyer Erin Hunnewell. One row per distinct receipt. ‘Sum of legible items’ is what was readable on the scans; ‘Printed total’ is the receipt's own total where the scan showed it. Where they differ, the scan was cut off (see each sheet's note).
A5: Receipt (sheet) | B5: Business | C5: Date / Time | D5: Sum of legible items | E5: Printed total
A6: Mad Moose 0806 | B6: Mad Moose Bar and Grill | C6: 08-05-26 08:06 | D6: ='Mad Moose 0806'!E39 -> 2084.47 | E6: —
A7: Moose Loose 0818 | B7: Moose on the Loose | C7: 08-05-26 08:18 | D7: ='Moose Loose 0818'!E40 -> 507.82 | E7: —
A8: Mad Moose 0815 recall | B8: Mad Moose Bar and Grill | C8: 08-05-26 08:15 | D8: ='Mad Moose 0815 recall'!E32 -> 675.46 | E8: 1094.14
A9: Moose I13372 0722 | B9: Moose on the Loose | C9: 07-22-26 09:28 | D9: ='Moose I13372 0722'!E55 -> 924.23 | E9: 3524.35
A10: Moose I26544 0804 | B10: Moose on the Loose | C10: 08-04-26 15:35 | D10: ='Moose I26544 0804'!E22 -> 398.71 | E10: —
A11: Moose I4710 0708 | B11: Moose on the Loose | C11: 07-08-26 07:42 | D11: ='Moose I4710 0708'!E29 -> 432.48 | E11: 3986.59
A12: Mad Moose I9681 0722 | B12: Mad Moose Bar and Grill | C12: 07-22-26 09:31 | D12: ='Mad Moose I9681 0722'!E45 -> 1859.35 | E12: —
A13: Mad Moose I968 0722 | B13: Mad Moose Bar and Grill | C13: 07-22-26 09:36 | D13: ='Mad Moose I968 0722'!E23 -> 603.27 | E13: 5217.23
A14: Mad Moose I23708 0721 | B14: Mad Moose Bar and Grill | C14: 07-21-26 14:59 | D14: ='Mad Moose I23708 0721'!E28 -> 57.22 | E14: —
A15: Moose I9588 0721 | B15: Moose on the Loose | C15: 07-21-26 14:56 | D15: ='Moose I9588 0721'!E22 -> 298.67 | E15: —
A16: Mad Moose I11777 0804 | B16: Mad Moose Bar and Grill (Bar w/ serving kitchen) | C16: 08-04-26 15:34 | D16: ='Mad Moose I11777 0804'!E28 -> 453.32 | E16: —
A17: Supplies 792.24 | B17: (customer header not captured) | D17: ='Supplies 792.24'!E24 -> 300.94 | E17: 792.24
A18: Supplies 784.19 | B18: (customer header not captured) | D18: ='Supplies 784.19'!E22 -> 421.83 | E18: 784.19
A19: Receipt S01 | B19: (customer header not captured) | D19: ='Receipt S01'!E49 -> 859.58 | E19: —
A20: Receipt S11 | B20: (customer header not captured) | D20: ='Receipt S11'!E51 -> 698 | E20: —

Sheet Receipt Index
A1: Receipt Index — distinct receipts & duplicate scans
A3: All uploads are Restaurant Depot Store #802 (Colonie, NY), buyer Erin Hunnewell. Same-file re-uploads and receipts photographed more than once were removed; each distinct receipt is kept once.
A5: Source file(s) | B5: Business | C5: Date / Time | D5: Transaction (Register · Invoice) | E5: Grand Total | F5: Status
A6: RD 86.pdf ×2 | B6: Mad Moose | C6: 08-05-26 08:06 | D6: C16 I15336 OP288797 | F6: In queue (2nd upload = duplicate, removed)
A7: Rd.pdf ×2 | B7: Moose on the Loose | C7: 08-05-26 08:18 | D7: C16 I15337 OP288797 | F7: In queue (2nd upload = duplicate, removed)
A8: Scan_0002 (+rd8602,0003) | B8: Mad Moose | C8: 08-05-26 08:15 | D8: C16 I15336 OP288797 | E8: 1094.14 | F8: NEW · added (dupes removed)
A9: Scan_0004 + 0005 (+0003,rd8602) | B9: Moose on the Loose | C9: 07-22-26 09:28 | D9: C16 I13372 OP289802 | E9: 3524.35 | F9: NEW · added (dupes removed)
A10: Scan_0005 (+rd8602) | B10: Moose on the Loose | C10: 08-04-26 15:35 | D10: C13 I26544 OP279671 | F10: NEW · added (partial scan)
A11: Scan_0006 | B11: Moose on the Loose | C11: 07-08-26 07:42 | D11: C18 I4710 OP279671 | E11: 3986.59 | F11: NEW · added (partial scan)
A12: Scan_0009 | B12: Mad Moose | C12: 07-22-26 09:31 | D12: C15 I9681 OP247304 | F12: NEW · added (total cut off)
A13: Scan_0010 | B13: Mad Moose | C13: 07-22-26 09:36 | D13: C15 I968x OP??? | E13: 5217.23 | F13: NEW · added (partial scan)
A14: Scan_0012 | B14: Mad Moose | C14: 07-21-26 14:59 | D14: C13 I23708 OP280210 | F14: NEW · added (partial scan)
A15: Scan_0008 (right) | B15: Moose on the Loose | C15: 07-21-26 14:56 | D15: C15 I9588 OP247304 | F15: NEW · added (partial scan)
A16: Scan_0007 (right) | B16: Mad Moose | C16: 08-04-26 15:34 | D16: C15 I11777 OP289802 | F16: NEW · added (upside-down, low confidence)
A17: Scan_0007 (left) | B17: Unidentified | C17: — | D17: (no header captured) | E17: 792.24 | F17: NEW · added (tail only, business unknown)
A18: Scan_0008 (left) | B18: Unidentified | C18: — | D18: (no header captured) | E18: 784.19 | F18: NEW · added (tail only, business unknown)
A19: Scan_0001 | B19: Unidentified | C19: — | D19: (no header captured) | F19: NEW · added (no header/total)
A20: Scan_0011 | B20: Unidentified | C20: — | D20: (no header captured) | F20: NEW · added (middle only)
A21: rd8603.pdf | B21: — (not a receipt) | C21: 06-09-26 | D21: VT DMV Driver/Vehicle Exam Report | F21: EXCLUDED · not a receipt

Sheet Mad Moose 0806
A1: Mad Moose Bar and Grill
A3: Transaction | B3: C16 I15336 OP288797 08-05-26 08:06
A4: Account | B4: 1016712288
A5: Payment | B5: (payment line not legible on scan)
A6: Receipt tallies | B6: Units Entered 23 · Cases 7 · Items Rung Up 30 · RW Items 16 · Units Count 62
A7: Note: Already in the workbook. Printed subtotal/tax/grand total were cut off on the scan.
A10: Description | B10: Item Code | C10: Pack / Detail | D10: Units | E10: Amount
A11: PROSCIUTTO DANIELE | B11: 207722013213 | C11: 13.21 LB @ $6.49/LB | D11: 1 | E11: 85.73
A12: PD BRUSSEL SPRT HALV 5# | B12: 030223063636 | C12: U | D12: 1 | E12: 11.87
A13: GROUND PORK 5LBS | B13: 027182106221 | C13: C · 1cs/7u | D13: 7 | E13: 69.62
A14: CHIC WNG JUMB PRTY | B14: 207720040006 | C14: 40 LB @ $1.79/LB | D14: 1 | E14: 71.6
A15: CHIC WNG JUMB PRTY | B15: 207720040006 | C15: 40 LB @ $1.79/LB | D15: 1 | E15: 71.6
A16: CHIC WNG JUMB PRTY | B16: 207720040006 | C16: 40 LB @ $1.79/LB | D16: 1 | E16: 71.6
A17: CHIC WNG JUMB PRTY | B17: 207720040006 | C17: 40 LB @ $1.79/LB | D17: 1 | E17: 71.6
A18: CHIC WNG JUMB PRTY | B18: 207720040006 | C18: 40 LB @ $1.79/LB | D18: 1 | E18: 71.6
A19: WRAP SPINACH 12CT | B19: 760695007035 | C19: C · 1cs/6u | D19: 6 | E19: 20.23
A20: CHZ MOZZ THIN SLCD 8/LB | B20: 031142005479 | C20: C · 1cs/8u | D20: 8 | E20: 35.64
A21: CHZ PARM SHV DOM 4/5LB | B21: 760695008551 | C21: C · 1cs/4u | D21: 4 | E21: 86.28
A22: BF ANG GROUND CHUK R/W | B22: 207928160407 | C22: 60.4 LB @ $5.36/LB | D22: 1 | E22: 323.74
A23: VOLUME ADJUSTMENT | C23: applied to preceding item | E23: -25.97
A24: BF ANG GROUND CHUK R/W | B24: 207928160902 | C24: 60.9 LB @ $4.93/LB | D24: 1 | E24: 300.24
A25: CHIC BNLS THIGH HALAL | B25: 207950240009 | C25: 40 LB @ $1.74/LB | D25: 1 | E25: 69.6
A26: PD BASIL 1LB | B26: 854342004017 | D26: 1 | E26: 7.42
A27: PD BASIL 1LB | B27: 854342004017 | D27: 1 | E27: 7.42
A28: PD GINGER 30LB/CS | B28: 646127900153 | D28: 1 | E28: 43.7
A29: LI SOUND OYSTERS 50CT | B29: 501900098000 | D29: 1 | E29: 42.31
A30: DISCOUNT | C30: 45.00% (appr #270772 Pam Smith) | E30: -19.04
A31: LI SOUND OYSTERS 50CT | B31: 501900098000 | D31: 1 | E31: 42.31
A32: DISCOUNT | C32: 45.00% (appr #270772 Pam Smith) | E32: -19.04
A33: BF ANG GROUND CHUK R/W | B33: 207928163309 | C33: 63.3 LB @ $4.93/LB | D33: 1 | E33: 312.07
A34: DISCOUNT | C34: 25.00% (appr #270772 Pam Smith) | E34: -78.02
A35: BF ANG GROUND CHUK R/W | B35: 207928163606 | C35: 63.6 LB @ $4.93/LB | D35: 1 | E35: 313.55
A36: DISCOUNT | C36: 25.00% (appr #270772 Pam Smith) | E36: -78.39
A37: CHIC BRST TNDR/OUT | B37: 207723280003 | C37: 80 LB @ $1.46/LB (UPC appr #270772) | D37: 1 | E37: 116.8
A38: CHIC BRST TNDR/OUT | B38: 207723240007 | C38: 40 LB @ $1.46/LB (UPC appr #270772) | D38: 1 | E38: 58.4
A39: Sum of legible line items | E39: =SUM(E11:E38) -> 2084.47

Sheet Moose Loose 0818
A1: Moose on the Loose
A3: Transaction | B3: C16 I15337 OP288797 08-05-26 08:18
A4: Account | B4: 80212569
A5: Payment | B5: (payment line not legible on scan)
A6: Receipt tallies | B6: Total Units Count 45
A7: Note: Already in the workbook. Two lines (WHTP CRM, 2nd PD ROMAINE) and the money totals were cut off.
A10: Description | B10: Item Code | C10: Pack / Detail | D10: Units | E10: Amount
A11: PD JALAPENO 5# BAG | B11: 732966005576 | C11: U | D11: 1 | E11: 8.55
A12: PD JALAPENO 5# BAG | B12: 732966005576 | C12: U | D12: 1 | E12: 8.55
A13: PD JALAPENO 5# BAG | B13: 732966005576 | C13: U | D13: 1 | E13: 8.55
A14: PD LEMON JUICE 1QT | B14: 725341333333 | C14: C · 1cs/6u | D14: 6 | E14: 35.32
A15: PD MINT 4OZ | B15: 810003005045 | D15: 1 | E15: 3.75
A16: PD ROSEMARY 1LB | B16: 854342004093 | D16: 1 | E16: 8.02
A17: WHTP CRM JF NONDRY 147 | C17: price not legible | D17: 1
A18: PD CUCUMBRS SELECT 50LB | B18: 020600425034 | D18: 1 | E18: 16.98
A19: PD CELERY CS | B19: 020600425584 | D19: 1 | E19: 37.98
A20: PD ONION VD/SWT 10LBS | B20: 020618000513 | C20: C · 1cs/60u | D20: 60 | E20: 553.8
A21: PD ONION VD/SWT 10LBS | B21: 020618000513 | C21: VC void | D21: -60 | E21: -553.8
A22: PD ONION VD/SWT 10LBS | B22: 020618000513 | C22: U | D22: 1 | E22: 9.33
A23: PD ONION VD/SWT 10LBS | B23: 020618000513 | C23: U | D23: 1 | E23: 9.33
A24: PD TURKISH FIG 20OZ | B24: 019175052608 | C24: U | D24: 1 | E24: 7.81
A25: PD TURKISH FIG 20OZ | B25: 019175052608 | C25: U | D25: 1 | E25: 7.81
A26: PD TURKISH FIG 20OZ | B26: 019175052608 | C26: U | D26: 1 | E26: 7.81
A27: PD TURKISH FIG 20OZ | B27: 019175052608 | C27: U | D27: 1 | E27: 7.81
A28: PD TURKISH FIG 20OZ | B28: 019175052608 | C28: U | D28: 1 | E28: 7.81
A29: PD PEPPER POBLANO CASE | B29: 732966099018 | D29: 1 | E29: 26.39
A30: PD CABBAGE BAG | B30: 020600426659 | D30: 1 | E30: 17.64
A31: CHZ CREAM LOAF JF 3LB | B31: 760695000005 | C31: C · 1cs/10u | D31: 10 | E31: 64.07
A32: CHZ GOAT PAIL 2/4LB2 | B32: 761657903044 | C32: C · 1cs/2u | D32: 2 | E32: 55.24
A33: CHZ GOAT PAIL 2/4LB2 | B33: 761657903044 | C33: C · 1cs/2u | D33: 2 | E33: 55.24
A34: CHZ BLU CRUM TC 5# | B34: 075805171231 | C34: U | D34: 1 | E34: 18.4
A35: PD SHRED CARROTS 5LB | B35: 030223050704 | C35: U | D35: 1 | E35: 10.09
A36: PD SHRED CARROTS 5LB | B36: 030223050704 | C36: U | D36: 1 | E36: 10.09
A37: PD A/BOY7 6 ROM HEART | B37: 740695651650 | C37: C · 1cs/7u | D37: 7 | E37: 32.27
A38: PD ROMAINE 24CT CS | B38: 740695651056 | D38: 1 | E38: 32.98
A39: PD ROMAINE 24CT CS | C39: price not legible | D39: 1
A40: Sum of legible line items | E40: =SUM(E11:E39) -> 507.82

Sheet Mad Moose 0815 recall
A1: Mad Moose Bar and Grill
A3: Transaction | B3: C16 I15336 OP288797 08-05-26 08:15
A4: Account | B4: 1016712288
A5: Payment | B5: US DEBIT / VISA · Approval 662026 · Ref 9987
A6: Receipt tallies | B6: Units Entered 41 · Cases 11 · Items Rung Up 52 · Units Count 139 · Subtotal $1,094.14 (RECALLED ref $2,678.51, #2, 31 items)
A7: Note: Source: Scan_0002 (rd8602 & Scan_0003 are duplicate captures, removed). ~11 middle items between CHZ RICOTA and FZ CHOC TRILOGY were not captured on the scans.
A10: Description | B10: Item Code | C10: Pack / Detail | D10: Units | E10: Amount
A11: PD STRAWBERRIES 1LB | B11: 812092030175 | C11: C · 1cs/8u | D11: 8 | E11: 18.95
A12: PD CABBAGE RED BOX | B12: 020600425973 | D12: 1 | E12: 21.19
A13: PD ASPARAGUS LRG | B13: 020600425850 | D13: 1 | E13: 53.38
A14: PD ASPARAGUS LRG | B14: 020600425850 | C14: V void | D14: -1 | E14: -53.38
A15: PD BRUSSEL SPROUTS 25LBS | B15: 020600427496 | D15: 1 | E15: 35.74
A16: FZ CKE CARROT HIGH 14SL | B16: 760695025947 | C16: U | D16: 1 | E16: 33.05
A17: FZ PIE KEY LIME 12SLIC | B17: 760695018086 | C17: U | D17: 1 | E17: 24.32
A18: FZ CKE LIMONCELLO 14SL | B18: 760695020256 | C18: U | D18: 1 | E18: 28.85
A19: FZ PIE KEY LIME 12SLIC | B19: 760695018086 | C19: U | D19: 1 | E19: 24.32
A20: TURKEY RTC FOIL | B20: 207757523381 | C20: 23.38 LB @ $3.96/LB | D20: 1 | E20: 92.58
A21: DRES KENS BUTRMLK 1GAL | B21: 041335088912 | C21: C · 1cs/4u | D21: 4 | E21: 62.22
A22: DRES KENS BUTRMLK 1GAL | B22: 041335088912 | C22: C · 1cs/4u | D22: 4 | E22: 62.22
A23: CHZ RICOTA W SUPRE 3LB | B23: 760695003228 | C23: C · 1cs/6u | D23: 6 | E23: 29.93
A24: … ~11 items not legible on scan … | C24: —
A25: FZ CHOC TRILOGY 6/5.75 | B25: 049578269037 | C25: U · case $76.19/6 | D25: 1 | E25: 21.01
A26: CHZ GOAT PAIL 2/4LB2 | B26: 761657903044 | C26: C · 1cs/2u | D26: 2 | E26: 55.24
A27: CHZ GOAT PAIL 2/4LB2 | B27: 761657903044 | C27: C · 1cs/2u | D27: 2 | E27: 55.24
A28: NAB OREO 6CT CKIE 72Z | B28: 044000047030 | D28: 1 | E28: 15.56
A29: NAB OREO 6CT CKIE (coupon) | B29: 112520 | C29: discount | E29: -1
A30: BTR CABOT SALT SLD 1LB | B30: 078354636374 | C30: C · 1cs/36u | D30: 36 | E30: 93
A31: WHIP CRM JF NONDRY 14Z | B31: 760695003624 | C31: U | D31: 1 | E31: 3.04
A32: Sum of legible line items | E32: =SUM(E11:E31) -> 675.46
A33: Printed receipt total (from scan) | E33: 1094.14

Sheet Moose I13372 0722
A1: Moose on the Loose
A3: Transaction | B3: C16 I13372 OP289802 07-22-26 09:28
A4: Account | B4: 80212569
A5: Payment | B5: CHASE VISA · Approval 05104I · Ref 0448
A6: Receipt tallies | B6: Total Units Entered 39 · Cases 14 · Items Rung Up 53 · Weighed Goods 819.35 lb · Units Count 120 · Subtotal $3,524.35
A7: Note: Source: Scan_0004 (head+middle) + Scan_0005 (tail). Scan_0003 & rd8602 are duplicate captures (removed). 53 items on receipt; ~43 legible, a dairy/bacon section may be partially missing.
A10: Description | B10: Item Code | C10: Pack / Detail | D10: Units | E10: Amount
A11: FZ EDAMAME IN POD 20/1LB | B11: 760695024964 | C11: U | D11: 1 | E11: 2.19
A12: FZ MUKIMAME JF 2LB | B12: 760695019199 | C12: U | D12: 1 | E12: 5.02
A13: PD CARROT STICKS 5LB | B13: 020600437105 | C13: 2X U @ $13.61 | D13: 2 | E13: 27.22
A14: PD ORANGE BELL BAG 5LB | B14: 699058000607 | C14: U | D14: 1 | E14: 9.21
A15: PD YELLOW BELL BAG 5LB | B15: 684924041143 | C15: U | D15: 1 | E15: 9.21
A16: PD BABY ARUGULA BW 3LB | B16: 611123540009 | D16: 1 | E16: 17.49
A17: PD BABY ARUGULA BW 3LB | B17: 611123540009 | D17: 1 | E17: 17.49
A18: PD LEMON JUICE 1QT | B18: 725341333333 | C18: C · 1cs/6u | D18: 6 | E18: 35.32
A19: PD CILANTRO BAG | B19: 030223014560 | C19: U | D19: 1 | E19: 4.52
A20: PD ORANGE BINS | B20: 096704001375 | C20: U | D20: 1 | E20: 10.92
A21: PD ICELES SCALLION 4/4# | B21: 850023090126 | C21: U | D21: 1 | E21: 9.95
A22: PD ICELES SCALLION 4/4# | C22: price not legible | D22: 1
A23: PD BLUEBERY 18OZ | B23: 812092030038 | C23: U | D23: 1 | E23: 2.95
A24: PD ROSEMARY 1LB | B24: 854342004093 | D24: 1 | E24: 8.02
A25: PD STRAWBERRIES 1LB | B25: 715756200023 | C25: C · 1cs/8u | D25: 8 | E25: 22.77
A26: PD PEPPER POBLANO CASE | B26: 732966099018 | D26: 1 | E26: 26.99
A27: PD PEPPER JALAPENO | B27: 732966081136 | D27: 1 | E27: 35.95
A28: PD ROMAINE 24CT CS | B28: 740695651056 | D28: 1 | E28: 29.95
A29: PD ROMAINE 24CT CS | B29: 740695651056 | D29: 1 | E29: 29.95
A30: PD 12X6 MINI CUCS 1LB | B30: 699058610622 | C30: U | D30: 1 | E30: 1.96
A31: PD 12X6 MINI CUCS 1LB | B31: 699058610622 | C31: U | D31: 1 | E31: 1.96
A32: PD 12X6 MINI CUCS 1LB | B32: 699058610622 | C32: U | D32: 1 | E32: 1.96
A33: PD 12X6 MINI CUCS 1LB | B33: 699058610622 | C33: U | D33: 1 | E33: 1.96
A34: PD PARSLEY ITL 6CT | B34: 020600426987 | D34: 1 | E34: 7.55
A35: PD SAGE | B35: 854342004109 | D35: 1 | E35: 9.01
A36: PD SPINACH 4/2.5 | B36: 030223011507 | C36: C · 1cs/4u | D36: 4 | E36: 24.93
A37: PD SPINACH 4/2.5 | B37: 030223011507 | C37: C · 1cs/4u | D37: 4 | E37: 24.93
A38: PD APL GRANY | B38: 812333012298 | D38: 1 | E38: 39.78
A39: PD BEETS LOOSE 25# CASE | B39: 020600425782 | D39: 1 | E39: 20.51
A40: PD PEPP RED FCY15 LB | B40: 020600427144 | D40: 1 | E40: 25.58
A41: PD AVOCADO HASS | B41: 020600426161 | D41: 1 | E41: 46.95
A42: PD CUCUMBRS SELECT 50LB | B42: 020600425034 | D42: 1 | E42: 16.98
A43: PD BASIL 1LB | B43: 854342004017 | D43: 1 | E43: 7.48
...

Sheet Moose I26544 0804
A1: Moose on the Loose
A3: Transaction | B3: C13 I26544 OP279671 08-04-26 15:35
A4: Account | B4: 80212569
A5: Payment | B5: (cut off on scan)
A6: Receipt tallies | B6: (totals cut off on scan)
A7: Note: Source: Scan_0005 (rd8602 is a duplicate capture, removed). Head of receipt only — bottom (remaining items + totals) cut off on the scan.
A10: Description | B10: Item Code | C10: Pack / Detail | D10: Units | E10: Amount
A11: A&E APPLE JUICE 16Z | B11: 076301580015 | C11: case $15.00 / 12 | D11: 1 | E11: 15
A12: A&E APPLE JUICE 16Z | B12: 076301580015 | C12: case $15.00 / 12 | D12: 1 | E12: 15
A13: HERSH KISSES LG BG 35.8Z | B13: 034000134809 | C13: U(TA) | D13: 1 | E13: 16.86
A14: MAYO KENS PREMIUM 1GAL | B14: 041335091110 | C14: C · 1cs/4u | D14: 4 | E14: 64.9
A15: MAYO KENS PREMIUM 1GAL | B15: 041335091110 | C15: C · 1cs/4u | D15: 4 | E15: 64.9
A16: SAUC MLD WING FRNK GAL | B16: 041500012216 | C16: C · 1cs/4u | D16: 4 | E16: 58.68
A17: OIL GREEK XTRA VGN 3LTR | B17: 706950123744 | C17: C · 1cs/4u | D17: 4 | E17: 99.6
A18: YEAST RED STAR DRY 2LB | B18: 117929157002 | C18: U | D18: 1 | E18: 8.94
A19: BALSAMIC GLZ FIG 12.9Z | B19: 760695019335 | C19: C · 1cs/6u | D19: 6 | E19: 31.43
A20: YORK PEPRP CHNGMKR .48Z | B20: 034000066421 | C20: U(TA) case $210.56/175 | D20: 1 | E20: 23.4
A21: … remaining items cut off on scan … | C21: —
A22: Sum of legible line items | E22: =SUM(E11:E21) -> 398.71

Sheet Moose I4710 0708
A1: Moose on the Loose
A3: Transaction | B3: C18 I4710 OP279671 07-08-26 07:42
A4: Account | B4: 80212569
A5: Payment | B5: (not legible)
A6: Receipt tallies | B6: Total Units Count 224 · Items Rung Up 92 · Subtotal $3,986.59 (RECALLED ref $2,932.40, #1, 44 items)
A7: Note: Source: Scan_0006. 92-item receipt; only ~17 lines legible (head + tail). Most of the middle is not captured.
A10: Description | B10: Item Code | C10: Pack / Detail | D10: Units | E10: Amount
A11: PD TOMATO GRAPE PINT | B11: 091234000096 | C11: C | D11: 1 | E11: 34.95
A12: … middle not captured on scan … | C12: —
A13: PD TURKISH FIG 20OZ | B13: 019175052608 | C13: U | D13: 1 | E13: 7.81
A14: PD TURKISH FIG 20OZ | B14: 019175052608 | C14: U | D14: 1 | E14: 7.81
A15: PD TURKISH FIG 20OZ | B15: 019175052608 | C15: U | D15: 1 | E15: 7.81
A16: PD TURKISH FIG 20OZ | B16: 019175052608 | C16: U | D16: 1 | E16: 7.81
A17: PD PEPPER GREEN XL JBO | B17: 020600427045 | D17: 1 | E17: 39.95
A18: PD SPINACH 4/2.5 | B18: 030223011507 | C18: C · 1cs/4u | D18: 4 | E18: 19.8
A19: PD SPINACH 4/2.5 | B19: 030223011507 | C19: C · 1cs/4u | D19: 4 | E19: 19.8
A20: PD PLD GARLIC 6/5 BAG | B20: 680444103453 | C20: C · 1cs/6u | D20: 6 | E20: 63
A21: PD AVOCADO HASS | B21: 020600426161 | D21: 1 | E21: 48.95
A22: PD CABBAGE BOX 6-14CT | B22: 020600426260 | D22: 1 | E22: 28.68
A23: PD CABBAGE BOX 6-14CT | B23: 020600426260 | D23: 1 | E23: 28.68
A24: PD BRUSSEL SPROUTS 25LBS | B24: 020600427496 | D24: 1 | E24: 40.69
A25: PD CARROT 5LB BAG | B25: 020600434067 | D25: 1 | E25: 5.23
A26: CHZ SMOKED GOUDA R/W | B26: 206588705775 | C26: 5.77 LB @ $3.94/LB | D26: 1 | E26: 22.73
A27: CHZ SMOKED GOUDA R/W | B27: 206588706390 | C27: 6.39 LB @ $3.94/LB | D27: 1 | E27: 25.18
A28: CHZ SMOKED GOUDA R/W | B28: 206588705997 | C28: 5.99 LB @ $3.94/LB | D28: 1 | E28: 23.6
A29: Sum of legible line items | E29: =SUM(E11:E28) -> 432.48
A30: Printed receipt total (from scan) | E30: 3986.59

Sheet Mad Moose I9681 0722
A1: Mad Moose Bar and Grill
A3: Transaction | B3: C15 I9681 OP247304 07-22-26 09:31
A4: Account | B4: 1016712288
A5: Payment | B5: (grand total cut off on scan)
A6: Receipt tallies | B6: Units Entered 26 · Cases 9 · Items Rung Up 35 · RW Items 18 · Units Count 76
A7: Note: Source: Scan_0009 (head + tail both captured). Grand-total dollar line cut off. Beef lines carry 50% discounts approved by #273903 (Susan).
A10: Description | B10: Item Code | C10: Pack / Detail | D10: Units | E10: Amount
A11: FZ MUKIMAME JF 2LB | B11: 760695019199 | C11: U | D11: 1 | E11: 5.02
A12: FZ MUKIMAME JF 2LB | B12: 760695019199 | C12: U | D12: 1 | E12: 5.02
A13: TURKEY RTC FOIL | B13: 207757524661 | C13: 24.66 LB @ $3.96/LB | D13: 1 | E13: 97.65
A14: PEPPERNI 12.5# MAM | B14: 760695014293 | C14: C · 1cs/2u | D14: 2 | E14: 80.54
A15: PD TOMATO ROMA XL 25LB | B15: 020600427625 | D15: 1 | E15: 22.95
A16: PD TOMATO 5X6 25LB | B16: 020600427601 | D16: 1 | E16: 23.95
A17: PD TOMATO 5X6 25LB | B17: 020600427601 | D17: 1 | E17: 23.95
A18: CHIC BRS BNL HALAL R/W | B18: 207950140002 | C18: 40 LB @ $1.78/LB | D18: 1 | E18: 71.2
A19: CHIC BRS BNL HALAL R/W | B19: 207950140002 | C19: 40 LB @ $1.78/LB | D19: 1 | E19: 71.2
A20: CHIC WNG JUMB PRTY | B20: 207720040006 | C20: 40 LB @ $1.95/LB | D20: 1 | E20: 78
A21: CHIC WNG JUMB PRTY | B21: 207720040006 | C21: 40 LB @ $1.95/LB | D21: 1 | E21: 78
A22: CHIC WNG JUMB PRTY | B22: 207720040006 | C22: 40 LB @ $1.95/LB | D22: 1 | E22: 78
A23: CHIC WNG JUMB PRTY | B23: 207720040006 | C23: 40 LB @ $1.95/LB | D23: 1 | E23: 78
A24: WRAP TOMATO 12CT | B24: 760695007073 | C24: C · 1cs/6u | D24: 6 | E24: 20.31
A25: WRAP TOMATO 12CT | B25: 760695007073 | C25: C · 1cs/6u | D25: 6 | E25: 20.31
A26: WRAP GARLIC HERB 12CT | B26: 760695007042 | C26: C · 1cs/6u | D26: 6 | E26: 20.38
A27: WRAP GARLIC HERB 12CT | B27: 760695007042 | C27: C · 1cs/6u | D27: 6 | E27: 20.38
A28: WRAP GARLIC HERB 12CT | B28: 760695007042 | C28: C · 1cs/6u | D28: 6 | E28: 20.38
A29: WRAP GARLIC HERB 12CT | B29: 760695007042 | C29: C · 1cs/6u | D29: 6 | E29: 20.38
A30: BF ANG GROUND CHUK R/W | B30: 207928159203 | C30: 59.2 LB @ $5.09/LB | D30: 1 | E30: 301.33
A31: VOLUME ADJUSTMENT | C31: applied to preceding item | E31: -11.84
A32: DISCOUNT | C32: 50.00% (appr #273903 Susan) | E32: -144.74
A33: BF ANG GROUND CHUK R/W | B33: 207928160605 | C33: 60.6 LB @ $4.89/LB | D33: 1 | E33: 296.33
A34: DISCOUNT | C34: 50.00% (appr #273903 Susan) | E34: -148.16
A35: BF ANG GROUND CHUK R/W | B35: 207928160209 | C35: 60.2 LB @ $4.89/LB | D35: 1 | E35: 294.38
A36: DISCOUNT | C36: 50.00% (appr #273903 Susan) | E36: -147.19
A37: BF ANG GROUND CHUK R/W | B37: 207928160605 | C37: 60.6 LB @ $4.89/LB | D37: 1 | E37: 296.33
A38: DISCOUNT | C38: 50.00% (appr #273903 Susan) | E38: -148.16
A39: BF ANG GROUND CHUK R/W | B39: 207928159005 | C39: 59.0 LB @ $4.89/LB | D39: 1 | E39: 288.51
A40: DISCOUNT | C40: 50.00% (appr #273903 Susan) | E40: -144.26
A41: BF ANG GROUND CHUK R/W | B41: 207928160001 | C41: 60.0 LB @ $4.89/LB | D41: 1 | E41: 293.4
A42: DISCOUNT | C42: 50.00% (appr #273903 Susan) | E42: -146.7
A43: BF ANG GROUND CHUK R/W | B43: 207928159104 | C43: 59.1 LB @ $4.89/LB | D43: 1 | E43: 289
...

Sheet Mad Moose I968 0722
A1: Mad Moose Bar and Grill
A3: Transaction | B3: C15 I968x OP??? 07-22-26 09:36
A4: Account | B4: 1016712288
A5: Payment | B5: CHASE VISA · Approval 019411 · Ref 0448
A6: Receipt tallies | B6: Total Units Count 113 · Items Rung Up 46 · Subtotal $5,217.23 (RECALLED ref $2,541.63, #1, 35 items)
A7: Note: Source: Scan_0010 (head + tail). Middle not captured. Invoice number partly illegible.
A10: Description | B10: Item Code | C10: Pack / Detail | D10: Units | E10: Amount
A11: EZ POKE TUNA 10LB | B11: (illegible) | D11: 1 | E11: 59.9
A12: OAT MILK ORIGINAL 32Z | B12: 044100156182 | C12: C · 1cs/6u | D12: 6 | E12: 21.82
A13: CREAM JI HALF&HALF 32OZ | B13: 760695019786 | C13: C · 1cs/12u | D13: 12 | E13: 27.2
A14: MCHDSH SANI 1UTEMP 5GAL | B14: 765574117225 | C14: (TA) | D14: 1 | E14: 41.99
A15: MCHDSH DETER LUTMP 5GAL | B15: 765574115498 | C15: (TA) | D15: 1 | E15: 64.99
A16: FRSHBRNZIN 16-800 R/W | B16: 207788022051 | C16: 22.05 LB @ $7.59/LB | D16: 1 | E16: 167.36
A17: VOLUME ADJUSTMENT | C17: applied to preceding item | E17: -5.29
A18: EGGS XL LOOSE BWN 15DZ | B18: 522892 | C18: case $16.89 / 15 | D18: 1 | E18: 16.89
A19: … middle not captured on scan … | C19: —
A20: CHX GV GRILL HALAL 10LBS | B20: 760695345533 | D20: 1 | E20: 63.77
A21: TULK PESTO FRESH 32Z | B21: 070607500203 | C21: C · 1cs/6u | D21: 6 | E21: 72.32
A22: TULK PESTO FRESH 32Z | B22: 070607500203 | C22: C · 1cs/6u | D22: 6 | E22: 72.32
A23: Sum of legible line items | E23: =SUM(E11:E22) -> 603.27
A24: Printed receipt total (from scan) | E24: 5217.23

Sheet Mad Moose I23708 0721
A1: Mad Moose Bar and Grill
A3: Transaction | B3: C13 I23708 OP280210 07-21-26 14:59
A4: Account | B4: 1016712288
A5: Payment | B5: (not captured)
A6: Receipt tallies | B6: (totals not captured)
A7: Note: Source: Scan_0012. Top (store header) and bottom (totals/payment) both cut off. Note the large #25 container line that was rung then voided.
A10: Description | B10: Item Code | C10: Pack / Detail | D10: Units | E10: Amount
A11: UTILITY TONG 7IN | B11: 812944008987 | C11: (TA) | D11: 1 | E11: 1.93
A12: UTILITY TONG 7IN | B12: 812944008987 | C12: (TA) | D12: 1 | E12: 1.93
A13: LEX PAN 1/9X4 | B13: 099511325603 | C13: C(TA) · 1cs/6u | D13: 6 | E13: 18.68
A14: LEX PAN 1/9X4 | B14: 099511325603 | C14: U(TA) | D14: 1 | E14: 3.12
A15: LEX PAN 1/9X4 | B15: 099511325603 | C15: U(TA) | D15: 1 | E15: 3.12
A16: #25 CONT REC BASE | B16: 051389410256 | C16: C(TA) · 1cs/220u | D16: 220 | E16: 694.35
A17: #25 CONT REC BASE | B17: 051389410256 | C17: VC void · -1cs/-220u | D17: -220 | E17: -694.35
A18: #25 CONT REC BASE | B18: 051389410256 | C18: U(TA) | D18: 1 | E18: 3.16
A19: #25 CONT REC BASE | B19: 051389410256 | C19: U(TA) | D19: 1 | E19: 3.16
A20: #25 CONT REC BASE | B20: 051389410256 | C20: U(TA) | D20: 1 | E20: 3.16
A21: #25 CONT REC BASE | B21: 051389410256 | C21: U(TA) | D21: 1 | E21: 3.16
A22: #25 CONT REC BASE | B22: 051389410256 | C22: U(TA) | D22: 1 | E22: 3.16
... A26: #25 CONT REC BASE | B26: 051389410256 | C26: U(TA) | D26: 1 | E26: 3.16
A27: … bottom cut off on scan … | C27: —
A28: Sum of legible line items | E28: =SUM(E11:E27) -> 57.22

Sheet Moose I9588 0721
A1: Moose on the Loose
A3: Transaction | B3: C15 I9588 OP247304 07-21-26 14:56
A4: Account | B4: 80212569
A5: Payment | B5: (cut off on scan)
A6: Receipt tallies | B6: (totals cut off on scan)
A7: Note: Source: Scan_0008 (right column). Head of receipt only — bottom cut off.
A10: Description | B10: Item Code | C10: Pack / Detail | D10: Units | E10: Amount
A11: PD ONION RED 20/2 | B11: 020600425652 | D11: 1 | E11: 51
A12: LINER 40G 40x46 CLR | B12: 760695006359 | C12: (TA) case $67.44/100 | D12: 1 | E12: 67.44
A13: A&W ROOT BEER CLUB 12Z | B13: 078000052138 | C13: (TA) case $13.83/24 | D13: 1 | E13: 13.83
A14: BOTTLE DEPOSIT 24CT | B14: 1090 | C14: S · $1.20/24 | D14: 1 | E14: 1.2
A15: VEG PEAS 4 SV LQ #10 | B15: 760695009565 | C15: C · 1cs/6u | D15: 6 | E15: 37.59
A16: BEAN KIDN D/RED CQ #10 | B16: 760695014743 | C16: C · 1cs/6u | D16: 6 | E16: 27.78
A17: BEAN BAKED B&M X #10 | B17: 047800330494 | C17: C · 1cs/6u | D17: 6 | E17: 47.82
A18: PIZZABOX 14 BR B CORR | B18: 584975 | C18: (TA) case $19.29/50 | D18: 1 | E18: 19.29
A19: PIZZABOX 14 BR B CORR | B19: 584975 | C19: (TA) case $19.29/50 | D19: 1 | E19: 19.29
A20: PIZZABOX 10 BR B CORR | B20: 584951 | C20: (TA) case $13.43/50 | D20: 1 | E20: 13.43
A21: … remaining items + totals cut off … | C21: —
A22: Sum of legible line items | E22: =SUM(E11:E21) -> 298.67

Sheet Mad Moose I11777 0804
A1: Mad Moose Bar and Grill (Bar w/ serving kitchen)
A3: Transaction | B3: C15 I11777 OP289802 08-04-26 15:34
A4: Account | B4: —
A5: Payment | B5: (not captured)
A6: Receipt tallies | B6: (totals not captured)
A7: Note: Source: Scan_0007 (right column) — printed UPSIDE-DOWN on the scan, so this transcription is LOW CONFIDENCE; verify against the original.
A10: Description | B10: Item Code | C10: Pack / Detail | D10: Units | E10: Amount
A11: TWL HARDWND WHI 12/350 | B11: 061328017958 | C11: (TA) case $28.96/12 | D11: 1 | E11: 28.96
A12: TWL HARDWND WHI 12/350 | B12: 061328017958 | C12: (TA) case $28.96/12 | D12: 1 | E12: 28.96
A13: CONT #2 10 60 KRAFT | B13: 760695029587 | C13: (TA) case $33.96/200 | D13: 1 | E13: 33.56
A14: REG ROLL 3"X200 1P THERM | B14: 760695337057 | C14: UC(TA) case $53.42/10 | D14: 1 | E14: 21.68
A15: 4 EVENT DIGI TIMER 5839N | B15: 077840288858 | C15: (TA) | D15: 1 | E15: 49.85
A16: PL FORK XHVY BLK SB | B16: 760695012459 | C16: C(TA) case $33.63/200 | D16: 5 | E16: 33.65
A17: BOTTLE DEPOSIT 24CT | B17: 1090 | C17: S · $1.20/24 | D17: 1 | E17: 1.2
A18: REDBULL SUD LIME 8.4Z | B18: 611269003655 | C18: (TA) case $40.09/24 | D18: 1 | E18: 40.09
A19: BOTTLE DEPOSIT 24CT | B19: 1090 | C19: S · $1.20/24 | D19: 1 | E19: 1.2
A20: REDBULL WHT PEACH 8.4Z | B20: 611269002690 | C20: (TA) case $41.15/24 | D20: 1 | E20: 41.15
A21: SAUC KNTUKY BOURBN GAL | B21: 041500968972 | C21: C · 1cs/2u | D21: 2 | E21: 31.37
A22: SAUC KNTUKY BOURBN GAL | B22: 041500968972 | C22: C · 1cs/2u | D22: 2 | E22: 31.37
... A26: SUNFLOWR RW CU 4.50LB | B26: (illegible) | C26: U | D26: 1 | E26: 11.5
A27: … rest not captured … | C27: —
A28: Sum of legible line items | E28: =SUM(E11:E27) -> 453.32

Sheet Supplies 792.24
A1: (customer header not captured)
A3: Transaction | B3: (no transaction line captured)
A4: Account | B4: —
A5: Payment | B5: DEBIT · Approval 098842 · Ref 4762
A6: Receipt tallies | B6: Items Rung Up 25 · Units Count 40 · Subtotal $754.64 · NY Tax $37.60 · Total $792.24
A7: Note: Source: Scan_0007 (left column). Tail of a supplies receipt; header/business and earlier items not captured, so it can't be tied to a specific store account. Likely one of the two businesses.
A10: Description | B10: Item Code | C10: Pack / Detail | D10: Units | E10: Amount
A11: LINER 33G 25X10X59 | B11: 760695039814 | C11: (TA) case $32.58/100 | D11: 1 | E11: 32.58
A12: NAPKINS 3PLY CHALET | B12: 061328071219 | C12: (TA) case $62.73/164 | D12: 1 | E12: 62.73
A13: MARGARITA FORTU GAL | B13: 070491012820 | C13: C(TA) · 1cs/4u | D13: 4 | E13: 35.49
A14: PEPPERONCINI SPRMO 1GAL | B14: 760695006090 | C14: U | D14: 1 | E14: 7.42
A15: KETCHUP CHEFS QLTY #10 | B15: 760695003099 | C15: C · 1cs/6u | D15: 6 | E15: 35.8
A16: VW ENERGY 20Z | B16: 786162101068 | C16: (TA) case $16.70/12 | D16: 1 | E16: 16.7
A17: FILM 12X2000 SUNSET | B17: 760695010509 | C17: (TA) | D17: 1 | E17: 13.34
A18: FILM 18X2000 SUNSET | B18: 760695010516 | C18: (TA) | D18: 1 | E18: 18
A19: CROUTON-DELI STYL 4/2.5# | B19: 760695022540 | C19: case $32.39/4 | D19: 1 | E19: 32.39
A20: CROUTON-DELI STYL 4/2.5# | B20: 760695022540 | C20: case $32.39/4 | D20: 1 | E20: 32.39
A21: 7-UP 12Z | B21: 078000011050 | C21: (TA) case $12.90/24 | D21: 1 | E21: 12.9
A22: BOTTLE DEPOSIT 24CT | B22: 1090 | C22: S · $1.20/24 | D22: 1 | E22: 1.2
A23: … earlier items not captured … | C23: —
A24: Sum of legible line items | E24: =SUM(E11:E23) -> 300.94
A25: Printed receipt total (from scan) | E25: 792.24

Sheet Supplies 784.19
A1: (customer header not captured)
A3: Transaction | B3: (no transaction line captured)
A4: Account | B4: —
A5: Payment | B5: US DEBIT · Approval 766037 · Ref 3089
A6: Receipt tallies | B6: Items Rung Up 23 · Units Count 55 · Subtotal $768.64 · NY Tax $15.55 · Total $784.19
A7: Note: Source: Scan_0008 (left column). Tail of a supplies/grocery receipt; header not captured.
A10: Description | B10: Item Code | C10: Pack / Detail | D10: Units | E10: Amount
A11: CRUTS PLAIN BUTTER 12/32 | B11: 894537000172 | C11: case $13.77/12 | D11: 1 | E11: 13.77
A12: CONT #2 TO GO KRAFT | B12: 760695029587 | C12: (TA) case $33.99/200 | D12: 1 | E12: 33.99
A13: HONEY LT AMBER CU 5LB | B13: 760695008230 | C13: C · 1cs/6u | D13: 6 | E13: 62.42
A14: OIL GREEK XTRA VGN 3LTR | B14: 706950123744 | C14: C · 1cs/4u | D14: 4 | E14: 99.6
A15: SAUC MED WING FRNK GAL | B15: 041500012216 | C15: C · 1cs/4u | D15: 4 | E15: 58.68
A16: HUNT TOM KETCHUP #10 | B16: 027000382516 | C16: C · 1cs/6u | D16: 6 | E16: 46.96
A17: UTZ JMB VARIETY BX 40.75Z | B17: 041780021786 | C17: case $18.29/42 | D17: 1 | E17: 18.29
A18: PS SPAG #5 BAR 2/10LB | B18: 076808039122 | C18: case $25.62/2 | D18: 1 | E18: 25.62
A19: DRES KENS CHIP MAY 1GAL | B19: 041335326205 | C19: C · 1cs/2u | D19: 2 | E19: 45.7
A20: MIX CHOC BRWNIE GM 6/5LB | B20: 016000113121 | C20: U | D20: 1 | E20: 16.8
A21: … earlier items not captured … | C21: —
A22: Sum of legible line items | E22: =SUM(E11:E21) -> 421.83
A23: Printed receipt total (from scan) | E23: 784.19

Sheet Receipt S01
A1: (customer header not captured)
A3: Transaction | B3: (no transaction line captured)
A4: Account | B4: —
A5: Payment | B5: (not captured)
A6: Receipt tallies | B6: Units Entered 22 · Cases 9 · Items Rung Up 31 · Units Count 77 (grand total cut off)
A7: Note: Source: Scan_0001 (produce + smallwares). No transaction header or grand total captured, so it can't be matched to a store account or de-duplicated with certainty.
A10: Description | B10: Item Code | C10: Pack / Detail | D10: Units | E10: Amount
A11: PD LIME JUICE 1QT | B11: 725341444435 | C11: VU void | D11: -1 | E11: -5.89
A12: PD YELLOW BELL BAG 5LB | B12: 628792010788 | C12: U | D12: 1 | E12: 7.94
A13: PD ORANGE BELL BAG 5LB | B13: 628792010771 | C13: U | D13: 1 | E13: 7.94
A14: PD CHERRY 6/3# | B14: 999495700710 | C14: U | D14: 1 | E14: 12.14
A15: PD STRAWBERRIES 1LB | B15: 715756200023 | C15: C · 1cs/8u | D15: 8 | E15: 22.95
A16: PD PEPPER GREEN XL JBO | B16: 020600427045 | D16: 1 | E16: 39.95
A17: PD PEPPER GREEN XL JBO | B17: 020600427045 | C17: V void | D17: -1 | E17: -39.95
A18: PD PEPP RED FCY15 LB | B18: 020600427144 | D18: 1 | E18: 27.95
A19: PD BLUEBERY 18OZ | B19: 812092030038 | C19: C · 1cs/8u | D19: 8 | E19: 38.95
A20: PD ICELES SCALLION 4/4# | B20: 850023090126 | C20: U | D20: 1 | E20: 9.72
A21: PD SHRED CARROTS 5LB | B21: 030223050704 | C21: U | D21: 1 | E21: 11.98
A22: PD SHRED CARROTS 5LB | B22: 030223050704 | C22: U | D22: 1 | E22: 11.98
A23: PD TOMATO GRAPE PINT | B23: 020600439062 | C23: C · 1cs/12u | D23: 12 | E23: 34.95
A24: PD TOMATO ROMA XL 25LB | B24: 020600427625 | D24: 1 | E24: 24.95
A25: PD PEPPER POBLANO CASE | B25: 732966099018 | D25: 1 | E25: 28.01
A26: PD TOMATO 5X6 25LB | B26: 020600427601 | D26: 1 | E26: 26.95
A27: PD TOMATO 5X6 25LB | B27: 020600427601 | D27: 1 | E27: 26.95
A28: PD ROMAINE 24CT CS | B28: 740695651056 | D28: 1 | E28: 39.95
A29: PD ROMAINE 24CT CS | B29: 033383651019 | D29: 1 | E29: 39.95
A30: PD JALAPENO 5# BAG | B30: 732966005576 | C30: C · 1cs/6u | D30: 6 | E30: 45.86
A31: CHZ ASIAGO SHRD SI 4/5LB | B31: 760695669813 | C31: U | D31: 1 | E31: 21.42
A32: SPOON S/S SOLID 13IN | B32: 800960183269 | C32: U(TA) | D32: 1 | E32: 1.54
A33: UTILITY TONG 7IN | B33: 812944008987 | C33: (TA) | D33: 1 | E33: 1.93
A34: UTILITY TONG 7IN | B34: 812944008987 | C34: (TA) | D34: 1 | E34: 1.93
A35: TONG SPRING 9IN HD | B35: 812944002022 | C35: (TA) | D35: 1 | E35: 2.62
A36: SUGAR CADDY BLACK | B36: 789313227518 | C36: U(TA) | D36: 1 | E36: 0.89
A37: SUGAR CADDY BLACK | B37: 789313227518 | C37: U(TA) | D37: 1 | E37: 0.89
A38: TIMER FLASHING/VIB 5879 | B38: 077784030783 | C38: (TA) | D38: 1 | E38: 13.67
A39: TUMBLERS 16Z CLEAR 1DZ | B39: 099511340408 | C39: U(TA) | D39: 1 | E39: 18.66
A40: DAWN 5GL DISH DTGT | B40: 037000123101 | C40: (TA) | D40: 1 | E40: 81.37
A41: NAPKINS 3PLY CHALET | B41: 061328071219 | C41: (TA) case $62.73/164 | D41: 1 | E41: 62.73
... A48: 10 1/4 DNR PLTE 8PK | B48: 789313999651 | C48: (TA) case $33.92/8 | D48: 1 | E48: 33.92
A49: Sum of legible line items | E49: =SUM(E11:E48) -> 859.58

Sheet Receipt S11
A1: (customer header not captured)
A3: Transaction | B3: (no transaction line captured)
A4: Account | B4: —
A5: Payment | B5: (not captured)
A6: Receipt tallies | B6: (no totals captured)
A7: Note: Source: Scan_0011 (two columns, middle of a supplies-heavy receipt). No header or totals captured. Includes a Mayo void and a Vinegar void.
A10: Description | B10: Item Code | C10: Pack / Detail | D10: Units | E10: Amount
A11: SP TACO SEASONING 5# | B11: 760695008506 | C11: U | D11: 1 | E11: 24.65
A12: YEAST RED STAR DRY 2LB | B12: 117929157002 | C12: U | D12: 1 | E12: 8.94
A13: DISINFEC DIAMOND 4/1GAL | B13: 765574071534 | C13: U(TA) | D13: 1 | E13: 22.92
A14: SP WHT GR PEP CQ 5LB | B14: 760695573615 | C14: U | D14: 1 | E14: 48.5
A15: SP LEM&PEPP SEASON 28Z | B15: 052100010793 | C15: U | D15: 1 | E15: 14.82
A16: OLV CASTELVERTANO 9LB | B16: 760695020751 | C16: U | D16: 1 | E16: 26.74
A17: MAYO KENS PREMIUM 1GAL | B17: 041335091110 | C17: U | D17: 1 | E17: 19.13
A18: MAYO KENS PREMIUM 1GAL | B18: 041335091110 | C18: U | D18: 1 | E18: 19.13
A19: MAYO KENS PREMIUM 1GAL | B19: 041335091110 | C19: 2X VU void (appr #280195 Sam) | D19: -2 | E19: -38.26
A20: MAYO KENS PREMIUM 1GAL | B20: 041335091110 | C20: C · 1cs/4u | D20: 4 | E20: 64.9
A21: BALSAMIC GLZ FIG 12.9Z | B21: 760695019335 | C21: C · 1cs/6u | D21: 6 | E21: 31.2
A22: VINEGAR BALSMIC CQ 5LTR | B22: 760695554027 | C22: U · case $23.21/2 | D22: 1 | E22: 12.42
... A49: CROUTON-DELI STYL 4/2.5# | B49: 760695022540 | C49: (TA) | D49: 1 | E49: 32.91
A50: … no header/totals captured … | C50: —
A51: Sum of legible line items | E51: =SUM(E11:E50) -> 698
